Workbook
Name Access: [1]Validation!$E$2:$E$223
Name AccessCircuit: [1]Validation!$C$2:$C$29
Name ACTION: #REF!
Name CoS: [1]Validation!$G$2:$G$47
Name Countries: [1]Validation!$A$2:$A$301
Name DSLCheckService: [1]Validation!$H$2:$H$4
Name Port: [1]Validation!$F$2:$F$40
Name VancoProducts: [1]Validation!$B$2:$B$4

Sheet Cover
B2: TEST CASE
B3: Version: | C3: 1.2
B4: Issue date: | C4: 45967
B6: Project Name: | C6: Shopệct OSS
B7: Project Code: | C7: SOSS-Online
B10: Record of change:
B11: Effective Date | C11: Version | D11: Change location | E11: Change description | F11: Originator | G11: Reviewer/ Approver | H11: Reference
B12: 45967 | C12: 1.0 | D12: Thay đổi các chức năng | E12: First creation | F12: Trần Hải Nam | G12: Trần Hải Nam | H12: SRS, Test Design

Sheet 1. Đăng ký
A1: TEST CASE
A3: System Name： | B3: Hệ thống tài khoản
A4: Module Code： | B4: REGx1 - Đăng ký tài khoản
A5: Test requirement: | B5: Người dùng chưa đăng nhập
A6: Pass | B6: =COUNTIF(K12:K15,"Pass") -> 3 | C6: Pending | D6: =COUNTIF(K10:K734,"Pending") -> 0
A7: Fail | B7: =COUNTIF(K12:K15,"Fail") -> 0 | C7: Number of test cases: | D7: =COUNTA(A13:A15) -> 3
A9: ID | B9: Test Case Description | C9: Test Case Procedure | D9: Expected Output | H9: Actual Result | I9: Test data | J9: Test date | K9: Result | L9: Note
A12: 1. Tạo tài khoản với email và password
A13: REG1 | B13: Đăng ký bằng mail hợp lệ | C13: 1. Mở trang đăng ký 2. Nhập Email và Password hợp lệ 3. Click Register | D13: Hiển thị thông báo 'Đăng ký thành công'; chuyển đến trang login | H13: 1. Đăng ký thành công 2. Chuyển đến trang login | I13: Email=user@example.com; Password=Pass123@ | J13: 45997 | K13: Pass | L13: No
A14: REG2 | B14: Đăng ký bằng email trùng | C14: 1. Mở trang đăng ký 2. Nhập Email đã tồn tại, click Register | D14: Hiển thị lỗi, 'Email đang được sử dụng' | H14: 1. Email đang được sử dụng | I14: Email=existing@example.com; Password=Pass123@ | J14: 14/06/2025 | K14: Pass | L14: No
A15: REG3 | B15: Đăng ký bằng Google Oauth | C15: 1. Mở trang đăng ký 2. Chọn "đăng nhập với Google" 3. Chọn tài khoản google hợp lệ, chờ callback | D15: Hiện thị thông báo "Đăng ký thành công' và chuyển đến trang sản phẩm chính | H15: 1. Đăng ký thành công 2. Chuyển đến trang chính | I15: Tài khoản Google hợp lệ | J15: 14/06/2025 | K15: Pass | L15: No
A16: REG4 | B16: Đăng ký bằng mật khẩu không đủ tiêu chuẩn | C16: 1. Mở trang đăng ký 2. Nhập email hợp lệ và password dưới 8 ký tự 3. Click Register | D16: Hiện thị thông báo "Mật khẩu không đủ 8 ký tự trở lên' | H16: 1. Mật khẩu không đủ 8 ký tự | I16: Email=user@example.com; Password=Pass123 | J16: 14/06/2025 | K16: Pass | L16: No

Sheet 2. Đăng nhập
A1: TEST CASE
A3: System Name： | B3: Hệ thống tài khoản
A4: Module Code： | B4: LOGx1 - Đăng nhập tài khoản
A5: Test requirement: | B5: Chưa đăng nhập
A6: Pass | B6: =COUNTIF(K12:K16,"Pass") -> 2 | C6: Pending | D6: =COUNTIF(K10:K735,"Pending") -> 0
A7: Fail | B7: =COUNTIF(K12:K16,"Fail") -> 1 | C7: Number of test cases: | D7: =COUNTA(A13:A15) -> 3
A9: ID | B9: Test Case Description | C9: Test Case Procedure | D9: Expected Output | H9: Actual Result | I9: Test data | J9: Test date | K9: Result | L9: Note
A12: 1. Kiểm tra đăng nhập với dữ liệu hợp lệ
A13: LOG1 | B13: Login đúng mật khẩu và email | C13: 1. Vào trang login 2. Nhập khớp mật khẩu và email, bấm login | D13: Hiển thị thông báo 'Đăng nhập thành công' | F13: Email=user@example.com; Password=WrongPass | H13: Đăng nhập thành công | I13: Email=user@example.com; Password=Pass123@ | J13: 15/06/2025 | K13: Pass
A14: 2. Kiểm tra đăng nhập với dữ liệu không hợp lệ
A15: LOG2 | B15: Login sai mật khẩu, đúng email | C15: 1. Vào trang login 2. Nhập sai mật khẩu và đúng email, bấm login | D15: Hiển thị lỗi 'Bạn nhập sai mật khẩu hoặc email' | H15: Bạn nhập sai mật khẩu | I15: Email=user@example.com; Password=Pass123 | J15: 15/06/2025 | K15: Fail | L15: Cần hiển thị đúng thông báo "Bạn nhập sai mật khẩu hoặc email", để gây tâm lý tránh tấn công phát hiện email tồn tại trên máy chủ
A16: LOG3 | B16: Login sai email, đúng mật khẩu | C16: 1. Vào trang login 2. Nhập đúng mật khẩu, sai email | D16: Hiển thị lỗi 'Bạn nhập sai mật khẩu hoặc email' | H16: Tài khoản không tồn tại | I16: Email=user2@example.com; Password=Pass123 | J16: 15/06/2025 | K16: Pass | L16: Cần hiển thị đúng thông báo "Bạn nhập sai mật khẩu hoặc email", để gây tâm lý tránh tấn công phát hiện email tồn tại trên máy chủ nếu nhập đúng mail

Sheet 3. Chỉnh sửa tài khoản
A1: TEST CASE
A3: System Name： | B3: Hệ thống tài khoản
A4: Module Code： | B4: EDTx1 - Chỉnh sửa tài khoản
A5: Test requirement: | B5: Đã đăng nhập tài khoản
A6: Pass | B6: =COUNTIF(K12:K15,"Pass") -> 3 | C6: Pending | D6: =COUNTIF(K10:K734,"Pending") -> 0
A7: Fail | B7: =COUNTIF(K12:K15,"Fail") -> 0 | C7: Number of test cases: | D7: =COUNTA(A13:A15) -> 3
A9: ID | B9: Test Case Description | C9: Test Case Procedure | D9: Expected Output | H9: Actual Result | I9: Test data | J9: Test date | K9: Result | L9: Note
A12: 1. Kiểm tra đăng nhập với dữ liệu hợp lệ
A13: EDT1 | B13: Chỉnh sửa tên | C13: 1. Vào Profile 2. Chọn phần tên 3. Nhấn edit | D13: Hiển thị thông báo 'Sửa tên thành công' | F13: Email=user@example.com; Password=WrongPass | H13: Sửa tên thành công | I13: Tên Họ = Trần Tên Đệm = Văn Tên = Lộc | J13: 15/06/2025 | K13: Pass
A14: EDT2 | B14: Chỉnh sửa mật khẩu | C14: 1. Vào Profile 2. Chọn phần mật khẩu 3. Nhấn edit 4. Nhập mật khẩu đủ tiêu chuẩn hợp lệ | D14: Hiển thị thông báo 'Đổi mật khẩu thành công' | H14: Đổi mật khẩu thành công | I14: test12345@@ | J14: 15/06/2025 | K14: Pass | L14: Test chỉ áp dụng cho tài khoản không đăng ký qua Google Account
A15: EDT3 | B15: Chỉnh sửa mật khẩu không đủ tiêu chuẩn | C15: 1. Vào Profile 2. Chọn phần mật khẩu 3. Nhấn edit 4. Nhập mật khẩu không đủ tiêu chuẩn | D15: Hiển thị lỗi 'Mật khẩu cần từ 8 ký tự trở lên' | H15: Mật khẩu cần 8 ký tự trở lên | I15: test123 | J15: 15/06/2025 | K15: Pass | L15: Test chỉ áp dụng cho tài khoản không đăng ký qua Google Account

Sheet 4. Thêm sản phầm vào giỏ hàng
A1: TEST CASE
A3: System Name： | B3: Hệ thống giỏ hàng
A4: Module Code： | B4: CRTx1 - Thêm sản phẩm vào giỏ hàng
A5: Test requirement: | B5: Đã đăng nhập tài khoản, sản phẩm còn hàng
A6: Pass | B6: =COUNTIF(K12:K15,"Pass") -> 2 | C6: Pending | D6: =COUNTIF(K10:K734,"Pending") -> 0
A7: Fail | B7: =COUNTIF(K12:K15,"Fail") -> 1 | C7: Number of test cases: | D7: =COUNTA(A13:A15) -> 3
A9: ID | B9: Test Case Description | C9: Test Case Procedure | D9: Expected Output | H9: Actual Result | I9: Test data | J9: Test date | K9: Result | L9: Note
A12: 1. Truyền vào giỏ hàng các dữ liệu món hàng
A13: CRT1 | B13: Thêm hàng vào giỏ | C13: 1. Trên trang chính bấm chọn món hàng A 2. Từ A nhấm thêm vào giỏ hàng | D13: Hiển thị thông báo 'Đã thêm vào giỏ hàng' | F13: Email=user@example.com; Password=WrongPass | H13: Đã thêm vào giỏ hàng | I13: Người dùng tương tác | J13: 16/06/2025 | K13: Pass
A14: CRT2 | B14: Xóa vật phẩm khỏi giỏ hàng | C14: 1. Từ trang chủ của giỏ hàng, chọn tích món hàng cần loại bỏ khỏi giỏ 2. Chọn Remove | D14: Món hàng sẽ bị xóa khỏi giỏ (Không có trả về) | H14: Hàng đã bị xóa khỏi giỏ hàng | I14: Người dùng tương tác | J14: 16/06/2025 | K14: Pass
A15: CRT3 | B15: Chỉnh sửa số lượng vật phẩm trong giỏ hàng | C15: 1. Từ trang chủ của giỏ hàng, chọn món hàng A 2. Nhấn dấu "+" để thêm vật phẩm và dấu "-" để bỏ bớt vật phẩm | D15: Nếu số lượng vật phẩm lớn 1 thì nhấn "-" hợp lệ Nếu số lượng vật phẩm từ 1 trở lên thì nhấn "+" hợp lệ | H15: Số lượng hàng A trong giỏ là 1, khi nhấn "-" thì giỏ báo còn 0 vật phẩm Số lượng hàng A trong giỏ là 1, khi nhấn "+" thì giỏ báo có 2 vật phẩm | I15: Người dùng tương tác | J15: 17/06/2025 | K15: Fail | L15: Nếu số lượng vật phẩm = 1 thì không thể nhấn "-"
A16: CRT4 | B16: Đặt hàng từ giỏ hàng | C16: 1. Từ trang chủ của giỏ hàng, chọn món hàng A 2. Nhấn nút "Đặt hàng" | D16: Chuyển đến trang thanh toán | H16: Chuyển đến trang thanh toán | I16: - | J16: 17/06/2025 | K16: Pass

Sheet 5. Đặt hàng
A1: TEST CASE
A3: System Name： | B3: Hệ thống đơn hàng
A4: Module Code： | B4: PAYx2 - Đặt hàng qua giỏ hàng
A5: Test requirement: | B5: Đã đăng nhập tài khoản, sản phẩm đã có trong giỏ
A6: Pass | B6: =COUNTIF(K13:K14,"Pass") -> 2 | C6: Pending | D6: =COUNTIF(K10:K731,"Pending") -> 0
A7: Fail | B7: =COUNTIF(K13:K14,"Fail") -> 0 | C7: Number of test cases: | D7: =COUNTA(A13:A14) -> 2
A9: ID | B9: Test Case Description | C9: Test Case Procedure | D9: Expected Output | H9: Actual Result | I9: Test data | J9: Test date | K9: Result | L9: Note
A12: 1. Truyền vào giỏ hàng các dữ liệu món hàng
A13: PAY11 | B13: Đặt hàng từ giỏ hàng | C13: 1. Từ trang chủ của giỏ hàng, chọn món hàng A 2. Nhấn nút "Đặt hàng" | D13: Chuyển đến trang thanh toán | H13: Chuyển đến trang thanh toán | I13: - | J13: 17/06/2025 | K13: Pass
A14: PAY12 | B14: Đặt hàng từ giỏ hàng trạng thái hàng đã hết | C14: 1. Từ trang chủ của giỏ hàng, chọn món hàng A 2. Nhấn nút "Đặt hàng" | D14: Báo lỗi "hàng đã hết" trước khi checkout | H14: Hàng đã hết | I14: - | J14: 17/06/2025 | K14: Pass

Sheet 6. Thanh toán
A1: TEST CASE
A3: System Name： | B3: Hệ thống thanh toán
A4: Module Code： | B4: Payx1 - Thanh toán bằng các phương thức khác
A5: Test requirement: | B5: Đã đăng nhập, Món hàng đang trong trạng thái checkout
A6: Pass | B6: =COUNTIF(K12:K15,"Pass") -> 3 | C6: Pending | D6: =COUNTIF(K10:K733,"Pending") -> 0
A7: Fail | B7: =COUNTIF(K12:K15,"Fail") -> 0 | C7: Number of test cases: | D7: =COUNTA(A13:A15) -> 3
A9: ID | B9: Test Case Description | C9: Test Case Procedure | D9: Expected Output | H9: Actual Result | I9: Test data | J9: Test date | K9: Result | L9: Note
A12: 1. Tiến hành thanh toán món hàng
A13: PAY1 | B13: Thanh toán tiền mặt | C13: 1. Từ trang checkout của đơn hàng, chọn phương thức thannh toán 2. Chọn "Thanh toán khi nhận hàng" | D13: Ghi nhận đơn, 'Order placed', hiện thông báo đặt hàng thành công | F13: Email=user@example.com; Password=WrongPass | H13: Đã ghi nhận đơn | I13: - | J13: 18/06/2025 | K13: Pass
A14: PAY2 | B14: Thanh toán trực tuyến | C14: 1. Từ trang checkout của đơn hàng, chọn phương thức thannh toán 2. Chọn "Thanh toán trực tuyến" 3. Điền thông tin thanh toán như thẻ tín dụng hoặc chọn ví điện tử 4. Nhấn nút thanh toán | D14: Ghi nhận đơn, 'Order placed', đã thanh toán hàng, hiện thông báo đặt hàng thành công | H14: Đã ghi nhận đơn, thanh toán thành công, hiện thông báo đặt hàng thành công | I14: - | J14: 18/06/2025 | K14: Pass
A15: PAY3 | B15: Lỗi thanh toán trực tuyến | C15: 1. Từ trang checkout của đơn hàng, chọn phương thức thannh toán 2. Chọn "Thanh toán trực tuyến" 3. Điền thông tin thanh toán như thẻ tín dụng hoặc chọn ví điện tử (cả 2 loại này đều đã bị khóa thẻ hoặc không có tiền) 4. Nhấn nút thanh toán | D15: Không ghi nhận đơn, báo lỗi "thanh toán không đủ tiền" hoặc "thanh toán không thành công" | H15: Thanh toán không đủ tiền | I15: - | J15: 18/06/2025 | K15: Pass

Sheet 7. Hủy đơn hàng
A1: TEST CASE
A3: System Name： | B3: Hệ thống đơn hàng
A4: Module Code： | B4: PAYx2 - Hủy đơn hàng
A5: Test requirement: | B5: Sản phẩm sau khi đã thanh toán thành công
A6: Pass | B6: =COUNTIF(K12:K14,"Pass") -> 1 | C6: Pending | D6: =COUNTIF(K10:K730,"Pending") -> 0
A7: Fail | B7: =COUNTIF(K12:K14,"Fail") -> 0 | C7: Number of test cases: | D7: =COUNTA(#REF!) -> 1
A9: ID | B9: Test Case Description | C9: Test Case Procedure | D9: Expected Output | H9: Actual Result | I9: Test data | J9: Test date | K9: Result | L9: Note
A12: 1. Truyền vào giỏ hàng các dữ liệu món hàng
A13: PAY21 | B13: Hủy đơn hàng | C13: 1. Từ khu vực đơn hàng 2. Nhấn nút hủy "đơn hàng" 3. Chọn confirm | D13: Đơn hàng hủy thành công | H13: Đơn hàng hủy thành công | I13: - | J13: 19/06/2025 | K13: Pass

Sheet 8. Đăng xuất
A1: TEST CASE
A3: System Name： | B3: Hệ thống tài khoản
A4: Module Code： | B4: EDTx2 - Đăng xuất
A5: Test requirement: | B5: Khi đã login
A6: Pass | B6: =COUNTIF(K12:K14,"Pass") -> 1 | C6: Pending | D6: =COUNTIF(K10:K730,"Pending") -> 0
A7: Fail | B7: =COUNTIF(K12:K14,"Fail") -> 0 | C7: Number of test cases: | D7: =COUNTA(#REF!) -> 1
A9: ID | B9: Test Case Description | C9: Test Case Procedure | D9: Expected Output | H9: Actual Result | I9: Test data | J9: Test date | K9: Result | L9: Note
A12: 1. Đăng xuất
A13: EDT21 | B13: Đăng xuất | C13: 1. Từ khu vực profile, chọn đăng xuất | D13: Tài khoản đăng xuất khỏi thiết bị, hiện thông báo, "tài khoản đã đăng xuất thành công" | H13: Đã đăng xuất khỏi thiết bị, "tài khoản đã đăng xuất thành công" | I13: - | J13: 19/06/2025 | K13: Pass

Sheet 9. Gửi hóa đơn mail
A1: TEST CASE
A3: System Name： | B3: Hệ thống thanh toán
A4: Module Code： | B4: Payx3 - Gửi hóa đơn mail
A5: Test requirement: | B5: Đã login, hàng đã được thanh toán thành công
A6: Pass | B6: =COUNTIF(K12:K14,"Pass") -> 2 | C6: Pending | D6: =COUNTIF(K10:K730,"Pending") -> 0
A7: Fail | B7: =COUNTIF(K12:K14,"Fail") -> 0 | C7: Number of test cases: | D7: =COUNTA(A13:A14) -> 2
A9: ID | B9: Test Case Description | C9: Test Case Procedure | D9: Expected Output | H9: Actual Result | I9: Test data | J9: Test date | K9: Result | L9: Note
A12: 1. Ghi nhận dữ liệu hóa đơn
A13: Pay31 | B13: Thực hiện gửi bản hóa đơn khi hàng được thanh toán | C13: 1. Từ khu vực thanh toán, thực hiện thanh toán 2. Hệ thống ghi nhận đơn hàng khi thanh toán thành công 3. Kiểm tra email gửi qua email đang dùng để đăng nhập, hóa đơn mẫu đơn hàng sẽ gửi vào hòm thư | D13: Kiểm tra hộp thư có nội dung hóa đơn đơn hàng đã tạo | H13: Kiểm tra hộp thư có nội dung hóa đơn | I13: - | J13: 19/06/2025 | K13: Pass
A14: Pay32 | B14: Tạo bản sao dữ liệu lên cơ sở dữ liệu | C14: 1. Từ khu vực thanh toán, thực hiện thanh toán 2. Hệ thống ghi nhận đơn hàng khi thanh toán thành công 3. Dữ liệu sẽ được ghi nhận bản sao vào cơ sở dữ liệu | D14: Có dữ liệu hóa đơn trên cơ sở dữ liệu | H14: Có dữ liệu hóa đơn trên cơ sở dữ liệu | I14: - | J14: 19/06/2025 | K14: Pass

Sheet Export all carrier choices
A1: TEST CASE
A3: System Name：
A4: Module Code： | B4: CR100 - Export to excel
A5: Test requirement: | B5: CR1 -
A6: Pass | B6: =COUNTIF(I12:I60,"Pass") -> 25 | C6: Pending | D6: =COUNTIF(I10:I782,"Pending") -> 0
A7: Fail | B7: =COUNTIF(I12:I60,"Fail") -> 1 | C7: Number of test cases: | D7: =COUNTA(A12:A63) -15 -> 37
A9: ID | B9: Test Case Description | C9: Test Case Procedure | D9: Expected Output | H9: Test date | I9: Result | J9: Note
A12: 1. Check add role "CanExportAllCarrierChoises": This will be typically set for System users only
A13: TC1 | B13: Checking new role is added | C13: 1: Go to the system TestProEngine with Classic or Current or Expert Mode 2: Go to maintenance 3: Click Maintenance Users 4: Click Role Tab | D13: Role Tab is added a new role, it's name "CanExportAllCarrierChoices" | I13: Pass
A14: Check set Role CanExportAllCarrierChoices = True
A15: TC2 | B15: Checking new function is added in Classic or Current Mode | C15: 1: Go to the system TestProEngine with Classic or Current Mode that has to set role "CanExportAllCarrierChoices" 2: Submit for the quote 3: Open the quote at the home 4: Go to Quick Links | D15: See a new selector: "Export all Carriers" | I15: Pass
A16: TC3 | B16: Checking new function is added in Classic or Current Mode | C16: 1: Go to the system TestProEngine with Classic or Current Mode that has to set role "CanExportAllCarrierChoices" 2: Unsubmit for the quote 3: Open the quote at the home 4: Go to Quick Links | D16: Don't see a new selector: "Export all Carriers" | I16: Pass
A17: TC4 | B17: Checking new function is added in Expert Mode | C17: 1: Go to the system TestProEngine with Expert Mode that has to set role "CanExportAllCarrierChoices" 2: Submit for the quote 3: Open the quote at the home 4: See on left Panel | D17: See a new menu item: "Export all Carriers" to be enabled in Current Quote Menu
A18: TC5 | B18: Checking new function is added in Expert Mode | C18: 1: Go to the system TestProEngine with Expert Mode that has to set role "CanExportAllCarrierChoices" 2:Unsubmit for the quote 3: Open the quote at the home 4: See on Left Panel | D18: See a new menu item: "Export all Carriers" to be disabled in Current Quote Menu
A19: Check set Role CanExportAllCarrierChoices = False
A20: TC6 | B20: Checking new function is added in Classic or Current Mode | C20: 1: Go to the system TestProEngine with Classic or Current Mode that has not to set role "CanExportAllCarrierChoices" 2: Submit for the quote 3: Open the quote at the home 4: Go to Quick Links | D20: Don't see a new selector: "Export all Carriers" | I20: Pass
A21: TC7 | B21: Checking new function is added in Classic or Current Mode | C21: 1: Go to the system TestProEngine with Classic or Current Mode that has not to set role "CanExportAllCarrierChoices" 2: Unsubmit for the quote 3: Open the quote at the home 4: Go to Quick Links | D21: Don't see a new selector: "Export all Carriers" | I21: Pass
A22: TC8 | B22: Checking new function is added in Expert Mode | C22: 1: Go to the system TestProEngine with Expert Mode that has not to set role "CanExportAllCarrierChoices" 2: Submit for the quote 3: Open the quote at the home 4: See on left Panel | D22: Don’t see a new menu item: "Export all Carriers" in Current Quote Menu
A23: TC9 | B23: Checking new function is added in Expert Mode | C23: 1: Go to the system TestProEngine with Expert Mode that has not to set role "CanExportAllCarrierChoices" 2:Unsubmit for the quote 3: Open the quote at the home 4: See on Left Panel | D23: Don’t see a new menu item: "Export all Carriers" in Current Quote Menu
A24: 2. Check Template of Excel when Export all Carriers
A25: TC10 | B25: Check performent of function in Current or Classic Mode has multi carrier support for a circuit | C25: 1: Go to the system TestProEngine with Current or Classic Mode 2: Create quote and submit 3: Click [Export all Carriers] on Quick Links | D25: 1: Will be the same content as CanSeeFullCostAndPriceBreakdown Role = False at the Current system 2: The export will not just contain one row for each circuit, but will contain one row for each carrier that can provide those circuits. The entire row details will be duplicated except the carrier name, price and carrier COS 3: A carrier will only be shown once for each circuit with its its aggregate IRD 4: Instead of only showing the total NRC and MRC, we will break out the price elements and show total NRC and MRC CLIENT PRICE for Access, Port, 6 CoS all separately, then Total – so 18 columns for figures in total 5: After the access, port, 6 CoS “requirement speeds”, should have 8 columns of speeds that have been priced See sheet Template A | I25: Pass
A26: TC11 | B26: Check performent of function in Current or Classic Mode each circuit has only one carrier support | C26: 1: Go to the system TestProEngine with Current or Classic Mode 2: Creat quote and Submit 3: Click [Export all Carriers] on Quick Links | D26: 1: Will be the same content as CanSeeFullCostAndPriceBreakdown Role = False at the Current system 2: The export show one row for each circuit has only one carrier support 3: A carrier will only be shown once for each circuit with its its aggregate IRD 4: Instead of only showing the total NRC and MRC, we will break out the price elements and show total NRC and MRC CLIENT PRICE for Access, Port, 6 CoS all separately, then Total – so 18 columns for figures in total 5: After the access, port, 6 CoS “requirement speeds”, should have 8 columns of speeds that have been priced See sheet Template A1 | I26: Pass
A27: TC12 | B27: Check performent of function in Expert Mode each circuit has only one carrier support | C27: 1: Go to the system TestProEngine with Expert Mode 2: Creat quote and submit 2: Click [Export all Carriers] button | D27: 1: Will be the same content as CanSeeFullCostAndPriceBreakdown Role = False at the Current system 2: The export show one row for each circuit has only one carrier support 3: A carrier will only be shown once for each circuit with its its aggregate IRD 4: Instead of only showing the total NRC and MRC, we will break out the price elements and show total NRC and MRC CLIENT PRICE for Access, Port, 6 CoS all separately, then Total – so 18 columns for figures in total 5: After the access, port, 6 CoS “requirement speeds”, should have 8 columns of speeds that have been priced 6: For Expert, this will contain the VSIP tables (selected VSIPs, selected VSIP capacities) which many be a table with no entries in it (All infomation in it are Blank) See sheet Template B1
A28: TC13 | B28: Check performent of function in Expert Mode Have multi carriers support for a circuit | C28: 1: Go to the system TestProEngine with Expert Mode 2: Creat quote and submit 3: Click [Export all Carriers] button | D28: 1: Will be the same content as CanSeeFullCostAndPriceBreakdown Role = False at the Current system 2: The export will not just contain one row for each circuit, but will contain one row for each carrier that can provide those circuits. The entire row details will be duplicated except the carrier name, price and carrier COS 3: A carrier will only be shown once for each circuit with its its aggregate IRD 4: Instead of only showing the total NRC and MRC, we will break out the price elements and show total NRC and MRC CLIENT PRICE for Access, Port, 6 CoS all separately, then Total – so 18 columns for figures in total 5: After the access, port, 6 CoS “requirement speeds”, should have 8 columns of speeds that have been priced 6: For Expert, this will contain the VSIP tables (selected VSIPs, selected VSIP capacities) which many be a table with no entries in it (All infomation in it are Blank) See sheet Template B
A29: 3. Check value of IRD column
A30: Set at the Current mode, Expert Mode, ClassicDIA Mode when site is MPLS + Role CanSeeCarrierName =True
A31: TC14 | B31: Check value of IRD column with Carrier for each circuit with its aggregate I, R | C31: 1: Go to the system TestProEngine with Current or Classic or Expert Mode 2: Creat quote and submit 3: Click [Export all Carriers] | D31: See IRD column in Template excel to show "IR" | I31: Pass
A32: TC15 | B32: Check value of IRD column with Carrier for each circuit with its aggregate I, R, D | C32: 1: Go to the system TestProEngine with Current or Classic or Expert Mode 2: Creat quote and submit 3: Click [Export all Carriers] | D32: See IRD column in Template excel to show "IRD" | I32: Pass
A33: TC16 | B33: Check value of IRD column with Carrier for each circuit with its aggregate I, D | C33: 1: Go to the system TestProEngine with Current or Classic or Expert Mode 2: Creat quote and submit 3: Click [Export all Carriers] | D33: See IRD column in Template excel to show "ID" | I33: Pass
A34: TC17 | B34: Check value of IRD column with Carrier for each circuit with its aggregate R, D | C34: 1: Go to the system TestProEngine with Current or Classic or Expert Mode 2: Creat quote and submit 3: Click [Export all Carriers] | D34: See IRD column in Template excel to show "RD" | I34: Pass
A35: TC18 | B35: Check value of IRD column with Carrier for each circuit with its aggregate I | C35: 1: Go to the system TestProEngine with Current or Classic or Expert Mode 2: Creat quote and submit 3: Click [Export all Carriers] | D35: See IRD column in Template excel to show "I" | I35: Pass
A36: TC19 | B36: Check value of IRD column with Carrier for each circuit with its aggregate D | C36: 1: Go to the system TestProEngine with Current or Classic or Expert Mode 2: Creat quote and submit 3: Click [Export all Carriers] | D36: See IRD column in Template excel to show "D" | I36: Pass
A37: TC20 | B37: Check value of IRD column with Carrier for each circuit with its aggregate R | C37: 1: Go to the system TestProEngine with Current or Classic or Expert Mode 2: Creat quote and submit 3: Click [Export all Carriers] | D37: See IRD column in Template excel to show "R" | I37: Pass
A38: Set at the Classic Mode, ClassicDIA Mode when site is DIA +Role CanSeeCarrierName = False
A39: TC21 | B39: Check value of IRD column with Carrier for each circuit with its aggregate IRD | C39: 1: Go to the system TestProEngine with ClassicDIA or Classic Mode 2: Creat quote(with ClassicDIA create site that is DIA) and submit 3: Click [Export all Carriers] at Quick Links | D39: See IRD column is tempalate to show "-" | I39: Pass
A40: 4. Check value of Notes/COS Selected column
A41: TC22 | B41: Check value of Note column if Set role CanSeeNotesAndCoSIndicator = True | C41: 1: Go to the system TestProEngine Current or Classic or Expert Mode 2: Create quote and submit for it 3: Go to Maintenance User set role CanSeeNotesAndCoSIndicator = True 4: Open the quote 5: Click [Export all Carriers] at Quick Links/Left Panel | D41: See Notes, COS selected column: value of them are Client notes/COS selected as on Pricing option popup | H41: Expert doesn't test | I41: Fail | J41: With Mode classic is fail ClassicDIA : Ok
A42: TC23 | B42: Check value of Note column if Set role CanSeeNotesAndCoSIndicator = False | C42: 1: Go to the system TestProEngine Current or Classic or Expert Mode 2: Create quote and submit for it 3: Go to Maintenance User set role CanSeeNotesAndCoSIndicator = False 4: Open the quote 5: Click [Export all Carriers] at Quick Links /Left panel | D42: See Notes, COS selected column: value of them are Blank | H42: Expert doesn't test | I42: Pass | J42: With Mode classic , ClassicDIA : Ok
A43: TC24 | B43: Check value of Note column if Access, Port, CoS Rule are mapping | C43: 1: Go to the system TestProEngine Current or Classic or Expert Mode 2: Create quote and submit for it 3: Open the quote 4: Click [Export all Carriers] at Quick Links /Left panel | D43: See value of Notes: show full information Access, Port, CoS rule to be mapping | H43: Expert doesn't test | I43: Pass | J43: With Mode classic , ClassicDIA : Ok
A44: 5. Check value of columns that provider supports
...

Sheet Test Report
A1: TEST REPORT
B3: Note: | C3: Nothing
B4: Date | C4: 20/06/2025
B7: No | C7: Module code | D7: Pass | E7: Fail | F7: Pending | G7: Number of test cases
B8: 1 | C8: ='1. Đăng ký'!B4 -> REGx1 - Đăng ký tài khoản | D8: ='1. Đăng ký'!B6 -> 3 | E8: ='1. Đăng ký'!B7 -> 0 | F8: ='1. Đăng ký'!D6 -> 0 | G8: ='1. Đăng ký'!D7 -> 3
B9: 2 | C9: ='2. Đăng nhập'!B4 -> LOGx1 - Đăng nhập tài khoản | D9: ='2. Đăng nhập'!B6 -> 2 | E9: ='2. Đăng nhập'!B7 -> 1 | F9: ='2. Đăng nhập'!D6 -> 0 | G9: ='2. Đăng nhập'!D7 -> 3
B10: 3 | C10: ='3. Chỉnh sửa tài khoản'!B4 -> EDTx1 - Chỉnh sửa tài khoản | D10: ='3. Chỉnh sửa tài khoản'!B6 -> 3 | E10: ='3. Chỉnh sửa tài khoản'!B7 -> 0 | F10: ='3. Chỉnh sửa tài khoản'!D6 -> 0 | G10: ='3. Chỉnh sửa tài khoản'!D7 -> 3
B11: 4 | C11: ='4. Thêm sản phầm vào giỏ hàng'!B4 -> CRTx1 - Thêm sản phẩm vào giỏ hàng | D11: ='4. Thêm sản phầm vào giỏ hàng'!B6 -> 2 | E11: ='4. Thêm sản phầm vào giỏ hàng'!B7 -> 1 | F11: ='4. Thêm sản phầm vào giỏ hàng'!D6 -> 0 | G11: ='4. Thêm sản phầm vào giỏ hàng'!D7 -> 3
B12: 5 | C12: ='5. Đặt hàng'!B4 -> PAYx2 - Đặt hàng qua giỏ hàng | D12: ='5. Đặt hàng'!B6 -> 2 | E12: ='5. Đặt hàng'!B7 -> 0 | F12: ='5. Đặt hàng'!D6 -> 0 | G12: ='5. Đặt hàng'!D7 -> 2
B13: 6 | C13: ='6. Thanh toán'!B4 -> Payx1 - Thanh toán bằng các phương thức khác | D13: ='6. Thanh toán'!B6 -> 3 | E13: ='6. Thanh toán'!B7 -> 0 | F13: ='6. Thanh toán'!D6 -> 0 | G13: ='6. Thanh toán'!D7 -> 3
B14: 7 | C14: ='7. Hủy đơn hàng'!B4 -> PAYx2 - Hủy đơn hàng | D14: ='7. Hủy đơn hàng'!B6 -> 1 | E14: ='7. Hủy đơn hàng'!B7 -> 0 | F14: ='7. Hủy đơn hàng'!D6 -> 0 | G14: ='7. Hủy đơn hàng'!D7 -> 1
B15: 8 | C15: ='8. Đăng xuất'!B4 -> EDTx2 - Đăng xuất | D15: ='8. Đăng xuất'!B6 -> 1 | E15: ='8. Đăng xuất'!B7 -> 0 | F15: ='8. Đăng xuất'!D6 -> 0 | G15: ='8. Đăng xuất'!D7 -> 1
B16: 9 | C16: ='9. Gửi hóa đơn mail'!B4 -> Payx3 - Gửi hóa đơn mail | D16: ='9. Gửi hóa đơn mail'!B6 -> 2 | E16: ='9. Gửi hóa đơn mail'!B7 -> 0 | F16: ='9. Gửi hóa đơn mail'!D6 -> 0 | G16: ='9. Gửi hóa đơn mail'!D7 -> 2
C18: Sub total | D18: =SUM(D8:D16) -> 19 | E18: =SUM(E8:E16) -> 2 | F18: =SUM(F8:F16) -> 0 | G18: =SUM(G8:G16) -> 21
C20: Test coverage | E20: =(D18+E18)*100/G18 -> 100 | F20: %
C21: Test successful coverage | E21: =D18*100/G18 -> 90.47619 | F21: %
